<?xml version="1.0" ?>
<!-- =================================================================================== -->
<!-- |    This document was autogenerated by xacro from puma560_robot.urdf.xacro       | -->
<!-- |    EDITING THIS FILE BY HAND IS NOT RECOMMENDED                                 | -->
<!-- =================================================================================== -->
<robot name="Puma560" xmlns:xacro="http://www.ros.org/wiki/xacro">
  <material name="blue">
    <color rgba="0 0 0.8 0.8"/>
  </material>
  <material name="red">
    <color rgba="0.8 0 0 0.8"/>
  </material>
  <material name="green">
    <color rgba="0 0.8 0 0.8"/>
  </material>
  <!-- DH Paramaters -->
  <link name="link1">
    <visual>
      <geometry>
        <mesh filename="package://puma560_description/meshes/base_link_.stl" scale="1 1 1"/>
      </geometry>
      <origin rpy="0 0 0"/>
      <material name="green"/>
    </visual>
  </link>
  <link name="link2">
    <visual>
      <geometry>
        <mesh filename="package://puma560_description/meshes/link1_.stl" scale="1 1 1"/>
      </geometry>
      <origin rpy="0 0 0" xyz="0 0 0"/>
      <material name="red"/>
    </visual>
  </link>
  <joint name="j1" type="revolute">
    <parent link="link1"/>
    <child link="link2"/>
    <origin rpy="0 0 0" xyz="0 0.065479 0.073"/>
    <axis xyz="0 0 -1"/>
    <!-- This is descibed in child frame -->
    <limit effort="100" lower="-1.57" upper="1.57" velocity="1"/>
  </joint>
  <link name="link3">
    <visual>
      <geometry>
        <mesh filename="package://puma560_description/meshes/link2_.stl" scale="1 1 1"/>
      </geometry>
      <origin xyz="0 0 0"/>
      <material name="blue"/>
    </visual>
  </link>
  <joint name="j2" type="revolute">
    <parent link="link2"/>
    <child link="link3"/>
    <origin rpy="0 0 0" xyz="-0.00015692 0 0.13096"/>
    <axis xyz="-1 0 0"/>
    <!-- This is descibed in child frame -->
    <limit effort="100" lower="-1.05" upper="1.05" velocity="1"/>
  </joint>
  <link name="link4">
    <visual>
      <geometry>
        <mesh filename="package://puma560_description/meshes/link3_.stl" scale="1 1 1"/>
      </geometry>
      <origin rpy="0 0 0" xyz="0 0 0"/>
      <material name="green"/>
    </visual>
  </link>
  <joint name="j3" type="revolute">
    <parent link="link3"/>
    <child link="link4"/>
    <origin rpy="0 0 0" xyz="0.049957 0 0.26254"/>
    <axis xyz="-1 0 0"/>
    <!-- This is descibed in child frame -->
    <limit effort="100" lower="-3.14" upper="0.79" velocity="1"/>
  </joint>
  <link name="link5">
    <visual>
      <geometry>
        <mesh filename="package://puma560_description/meshes/link4_.stl" scale="1 1 1"/>
      </geometry>
      <origin rpy="0 0 0" xyz="0 0 0"/>
      <material name="red"/>
    </visual>
  </link>
  <joint name="j4" type="revolute">
    <parent link="link4"/>
    <child link="link5"/>
    <origin rpy="0 0 0" xyz="-0.0498 0.078 0"/>
    <axis xyz="0 1 0"/>
    <limit effort="1000.0" lower="-1.570796325" upper="1.570796325" velocity="0"/>
  </joint>
  <link name="link6">
    <visual>
      <geometry>
        <mesh filename="package://puma560_description/meshes/link5_.stl" scale="1 1 1"/>
      </geometry>
      <origin rpy="0 0 0" xyz="0 0 0"/>
      <material name="green"/>
    </visual>
  </link>
  <joint name="j5" type="revolute">
    <parent link="link5"/>
    <child link="link6"/>
    <origin rpy="0 0 0" xyz="0.039767 0.13973 0"/>
    <axis xyz="-1 0 0"/>
    <limit effort="1000.0" lower="-1.570796325" upper="1.570796325" velocity="0"/>
  </joint>
  <link name="link7">
    <visual>
      <geometry>
        <mesh filename="package://puma560_description/meshes/link6__.stl" scale="1 1 1"/>
      </geometry>
      <origin rpy="0 0 0" xyz="0 0 0"/>
      <material name="blue"/>
    </visual>
  </link>
  <joint name="j6" type="revolute">
    <parent link="link6"/>
    <child link="link7"/>
    <origin rpy="0 0 0" xyz="-0.039767 0.06367 0"/>
    <axis xyz="0 1 0"/>
    <limit effort="1000.0" lower="-1.570796325" upper="1.570796325" velocity="0"/>
  </joint>
  <link name="gripper">
    <visual>
      <geometry>
        <mesh filename="package://puma560_description/meshes/gripper.stl" scale="1 1 1"/>
      </geometry>
      <origin rpy="0 0 0" xyz="0 0 0"/>
      <material name="blue"/>
    </visual>
  </link>
  <joint name="gripper_" type="fixed">
    <parent link="link7" />
    <child link="gripper" />
    <axis xyz="0 0 0" />
  </joint>
</robot>