<?xml version="1.0" ?>
<!-- =================================================================================== -->
<!-- |    This document was autogenerated by xacro from puma560_robot.urdf.xacro       | -->
<!-- |    EDITING THIS FILE BY HAND IS NOT RECOMMENDED                                 | -->
<!-- =================================================================================== -->
<robot name="Puma560" xmlns:xacro="http://www.ros.org/wiki/xacro">
  <material name="blue">
    <color rgba="0 0 0.8 0.8"/>
  </material>
  <material name="red">
    <color rgba="0.8 0 0 0.8"/>
  </material>
  <material name="green">
    <color rgba="0 0.8 0 0.8"/>
  </material>
  <!-- DH Paramaters -->
  <link name="link1">
    <visual>
      <geometry>
        <mesh filename="package://puma560_description/meshes/base_link-.stl" scale="1 1 1"/>
      </geometry>
      <origin rpy="0 0 0"/>
      <material name="green"/>
    </visual>
  </link>
  <link name="link2">
    <visual>
      <geometry>
        <mesh filename="package://puma560_description/meshes/link1-.stl" scale="1 1 1"/>
      </geometry>
      <origin rpy="0 0 0" xyz="0 0 0"/>
      <material name="red"/>
    </visual>
  </link>
  <joint name="j1" type="revolute">
    <parent link="link1"/>
    <child link="link2"/>
    <origin rpy="0 0 0" xyz="0 0 0.073"/>
    <axis xyz="0 0 -1"/>
    <!-- This is descibed in child frame -->
    <limit effort="100" lower="-1.5708" upper="1.5708" velocity="100"/>
  </joint>
  <link name="link3">
    <visual>
      <geometry>
        <mesh filename="package://puma560_description/meshes/link2-.stl" scale="1 1 1"/>
      </geometry>
      <origin xyz="0 0 0"/>
      <material name="blue"/>
    </visual>
  </link>
  <joint name="j2" type="revolute">
    <parent link="link2"/>
    <child link="link3"/>
    <origin rpy="0 0 0" xyz="0.09 0 0.1335"/>
    <axis xyz="-1 0 0"/>
    <!-- This is descibed in child frame -->
    <limit effort="100" lower="-1.0472" upper="1.0472" velocity="100"/>
  </joint>
  <link name="link4">
    <visual>
      <geometry>
        <mesh filename="package://puma560_description/meshes/link3-.stl" scale="1 1 1"/>
      </geometry>
      <origin rpy="0 0 0" xyz="0 0 0"/>
      <material name="green"/>
    </visual>
  </link>
  <joint name="j3" type="revolute">
    <parent link="link3"/>
    <child link="link4"/>
    <origin rpy="0 0 0" xyz="-0.0344 0 0.26"/>
    <axis xyz="-1 0 0"/>
    <!-- This is descibed in child frame -->
    <limit effort="100" lower="-0.7854" upper="0.7854" velocity="100"/>
  </joint>
  <link name="link5">
    <visual>
      <geometry>
        <mesh filename="package://puma560_description/meshes/link4-.stl" scale="1 1 1"/>
      </geometry>
      <origin rpy="0 0 0" xyz="0 0 0"/>
      <material name="red"/>
    </visual>
  </link>
  <joint name="j4" type="revolute">
    <parent link="link4"/>
    <child link="link5"/>
    <origin rpy="0 0 0" xyz="-0.0556 0.068 0"/>
    <axis xyz="0 1 0"/>
    <limit effort="100" lower="-2.3562" upper="2.3562" velocity="100"/>
  </joint>
  <link name="link6">
    <visual>
      <geometry>
        <mesh filename="package://puma560_description/meshes/link5-.stl" scale="1 1 1"/>
      </geometry>
      <origin rpy="0 0 0" xyz="0 0 0"/>
      <material name="green"/>
    </visual>
  </link>
  <joint name="j5" type="revolute">
    <parent link="link5"/>
    <child link="link6"/>
    <origin rpy="0 0 0" xyz="0.046 0.15 0"/>
    <axis xyz="-1 0 0"/>
    <limit effort="100" lower="-1.5708" upper="1.5708" velocity="100"/>
  </joint>
  <link name="link7">
    <visual>
      <geometry>
        <mesh filename="package://puma560_description/meshes/link6-.stl" scale="1 1 1"/>
      </geometry>
      <origin rpy="0 0 0" xyz="0 0 0"/>
      <material name="blue"/>
    </visual>
  </link>
  <joint name="j6" type="revolute">
    <parent link="link6"/>
    <child link="link7"/>
    <origin rpy="0 0 0" xyz="-0.046 0.0534 0"/>
    <axis xyz="0 1 0"/>
    <limit effort="100" lower="-3.1415" upper="3.1415" velocity="100"/>
  </joint>
  <link name="gripper_base">
    <visual>
      <geometry>
        <mesh filename="package://puma560_description/meshes/gripper_base-.stl" scale="1 1 1"/>
      </geometry>
      <origin rpy="0 0 0" xyz="0 0 0"/>
      <material name="blue"/>
    </visual>
  </link>
  <joint name="joint_gripper_base" type="fixed">
    <parent link="link7"/>
    <child link="gripper_base"/>
    <origin rpy="0 0 0" xyz="-0.01 0.1085 0"/>
    <axis xyz="0 0 0" />
  </joint>
  <link name="finger">
    <visual>
      <geometry>
        <mesh filename="package://puma560_description/meshes/finger-.stl" scale="1 1 1"/>
      </geometry>
      <origin rpy="0 0 0" xyz="0 0 0"/>
      <material name="blue"/>
    </visual>
  </link>
  <joint name="joint_finger" type="prismatic">
    <parent link="gripper_base"/>
    <child link="finger"/>
    <origin rpy="0 0 0" xyz="0 0 0"/>
    <axis xyz="1 0 0" />
    <limit effort="100" lower="0" upper="0.037" velocity="100"/>
  </joint>
</robot>